<?xml version="1.0"?>
<robot name="hand">

    <!-- Base Link -->
    <link name="base_link">
        <inertial>
            <mass value="1.0" />
            <origin xyz="0 0 0" rpy="0 0 0"/>
            <inertia ixx="0.1" ixy="0" ixz="0" iyy="0.1" iyz="0" izz="0.1" />
        </inertial>
        <visual>
            <origin xyz="0.0 0.0 -0.024" rpy="0.0 0.0 0.0"/>
            <geometry>
                <cylinder radius="0.02" length="0.048"/>
            </geometry>
        </visual>
    </link>

    <!-- Link 1 -->
    <link name="wrist">
        <inertial>
            <mass value="0.5" />
            <origin xyz="0 0 0" rpy="0 0 0"/>
            <inertia ixx="0.05" ixy="0" ixz="0" iyy="0.05" iyz="0" izz="0.05" />
        </inertial>
        <visual>
            <origin xyz="0.0 0.0 0.008" rpy="0.0 0.0 0.0"/>
            <geometry>
                <cylinder radius="0.005" length="0.016"/>
            </geometry>
        </visual>
    </link>

    <!-- Joint 1 -->
    <joint name="joint1" type="revolute">
        <parent link="base_link"/>
        <child link="wrist"/>
        <origin xyz="0 0 0" rpy="0 0 0"/>
        <axis xyz="0 1 0"/>
        <limit lower="-0.40" upper="0.40" effort="10" velocity="1"/>
    </joint>

    <!-- Link 2 -->
    <link name="meta2_c">
        <inertial>
            <mass value="0.5" />
            <origin xyz="0 0 0" rpy="0 0 0"/>
            <inertia ixx="0.05" ixy="0" ixz="0" iyy="0.05" iyz="0" izz="0.05" />
        </inertial>
        <visual>
            <origin xyz="0.0 0.0 0.0" rpy="0.0 0.0 0.0"/>
            <geometry>
                <cylinder radius="0.005" length="0.016"/>
            </geometry>
        </visual>
    </link>

    <!-- Joint 2 -->
    <joint name="joint2" type="revolute">
        <parent link="wrist"/>
        <child link="meta2_c"/>
        <origin xyz="0.0011 -0.0025 0.0326447" rpy="0 0 0"/>
        <!-- .785398 0 0 -->
        <axis xyz="1 0 0"/>
        <limit lower="-1.57" upper="1.57" effort="10" velocity="1"/>
    </joint>

    <!-- Link 3 -->
    <link name="meta1_c_1">
        <inertial>
            <mass value="0.5" />
            <origin xyz="0 0 0" rpy="0 0 0"/>
            <inertia ixx="0.05" ixy="0" ixz="0" iyy="0.05" iyz="0" izz="0.05" />
        </inertial>
    </link>
    <link name="meta1_c_2">
        <inertial>
            <mass value="0.5" />
            <origin xyz="0 0 0" rpy="0 0 0"/>
            <inertia ixx="0.05" ixy="0" ixz="0" iyy="0.05" iyz="0" izz="0.05" />
        </inertial>
    </link>
    <link name="meta1_c_3">
        <inertial>
            <mass value="0.5" />
            <origin xyz="0 0 0" rpy="0 0 0"/>
            <inertia ixx="0.05" ixy="0" ixz="0" iyy="0.05" iyz="0" izz="0.05" />
        </inertial>
        <visual>
            <origin xyz="0.0 0.0 0.0" rpy="0.0 0.0 0.0"/>
            <geometry>
                <cylinder radius="0.005" length="0.032"/>
            </geometry>
        </visual>
    </link>

    <!-- Joint 3 -->
    <joint name="joint3_1" type="fixed">
        <parent link="meta2_c"/>
        <child link="meta1_c_1"/>
        <origin xyz="-0.0096137 -0.00165902 0.0489203" rpy="0.002443461 0 0"/>
        <axis xyz="0 0 0"/>
        <limit lower="-3.14" upper="3.14" effort="10" velocity="1"/>
    </joint>
    <joint name="joint3_2" type="fixed">
        <parent link="meta1_c_1"/>
        <child link="meta1_c_2"/>
        <origin xyz="0 0 0" rpy="0 -0.06021386 0"/>
        <axis xyz="0 0 0"/>
        <limit lower="-3.14" upper="3.14" effort="10" velocity="1"/>
    </joint>
    <joint name="joint3_3" type="revolute">
        <parent link="meta1_c_2"/>
        <child link="meta1_c_3"/>
        <origin xyz="0 0 0" rpy="0 0 0"/>
        <axis xyz="0 0 1"/>
        <limit lower="-0.08" upper="0.08" effort="10" velocity="1"/>
    </joint>

    <!-- Link 4 -->
    <link name="indexp1_c_1">
        <inertial>
            <mass value="0.5" />
            <origin xyz="0 0 0" rpy="0 0 0"/>
            <inertia ixx="0.05" ixy="0" ixz="0" iyy="0.05" iyz="0" izz="0.05" />
        </inertial>
    </link>
    <link name="indexp1_c_2">
        <inertial>
            <mass value="0.5" />
            <origin xyz="0 0 0" rpy="0 0 0"/>
            <inertia ixx="0.05" ixy="0" ixz="0" iyy="0.05" iyz="0" izz="0.05" />
        </inertial>
    </link>
    <link name="indexp1_c_3">
        <inertial>
            <mass value="0.5" />
            <origin xyz="0 0 0" rpy="0 0 0"/>
            <inertia ixx="0.05" ixy="0" ixz="0" iyy="0.05" iyz="0" izz="0.05" />
        </inertial>
        <visual>
            <origin xyz="0.0 0.0 0.0" rpy="0.0 0.0 0.0"/>
            <geometry>
                <cylinder radius="0.005" length="0.005"/>
            </geometry>
        </visual>
    </link>

    <!-- Joint 4 -->
    <joint name="joint4_1" type="fixed">
        <parent link="meta1_c_3"/>
        <child link="indexp1_c_1"/>
        <origin xyz="-0.0138285 -0.00145 0.0301857" rpy="-0.0028797933 0 0"/>
        <axis xyz="0 0 0"/>
        <limit lower="-3.14" upper="3.14" effort="10" velocity="1"/>
    </joint>
    <joint name="joint4_2" type="fixed">
        <parent link="indexp1_c_1"/>
        <child link="indexp1_c_2"/>
        <origin xyz="0 0 0" rpy="0 0 -0.04258603"/>
        <axis xyz="0 0 0"/>
        <limit lower="-3.14" upper="3.14" effort="10" velocity="1"/>
    </joint>
    <joint name="joint4_3" type="revolute">
        <parent link="indexp1_c_2"/>
        <child link="indexp1_c_3"/>
        <origin xyz="0 0 0" rpy="0 0 0"/>
        <axis xyz="0 1 0"/>
        <limit lower="-0.27" upper="0.27" effort="10" velocity="1"/>
    </joint>

    <!-- Link 5 -->
    <link name="indexp2_c">
        <inertial>
            <mass value="0.5" />
            <origin xyz="0 0 0" rpy="0 0 0"/>
            <inertia ixx="0.05" ixy="0" ixz="0" iyy="0.05" iyz="0" izz="0.05" />
        </inertial>
        <visual>
            <origin xyz="0.0 0.0 0.0" rpy="0.0 0.0 0.0"/>
            <geometry>
                <cylinder radius="0.005" length="0.005"/>
            </geometry>
        </visual>
    </link>

    <!-- Joint 5 -->
    <joint name="joint5" type="revolute">
        <parent link="indexp1_c_3"/>
        <child link="indexp2_c"/>
        <origin xyz="-0.000099998 -0.0016 0.014" rpy="0 0 0"/>
        <axis xyz="1 0 0"/>
        <limit lower="-1.57" upper="0.17" effort="10" velocity="1"/>
    </joint>

    <!-- Link 6 -->
    <link name="indexp3_c">
        <inertial>
            <mass value="0.5" />
            <origin xyz="0 0 0" rpy="0 0 0"/>
            <inertia ixx="0.05" ixy="0" ixz="0" iyy="0.05" iyz="0" izz="0.05" />
        </inertial>
        <visual>
            <origin xyz="0.0 0.0 0.0" rpy="0.0 0.0 0.0"/>
            <geometry>
                <cylinder radius="0.005" length="0.005"/>
            </geometry>
        </visual>
    </link>

    <!-- Joint 6 -->
    <joint name="joint6" type="revolute">
        <parent link="indexp2_c"/>
        <child link="indexp3_c"/>
        <origin xyz="0 0.00199797 0.048" rpy="0 0 0"/>
        <!-- -1.5708 0 0-->
        <axis xyz="1 0 0"/>
        <limit lower="-2.10" upper="0" effort="10" velocity="1"/>
    </joint>

    <!-- Link 7 -->
    <link name="indexp4_c">
        <inertial>
            <mass value="0.5" />
            <origin xyz="0 0 0" rpy="0 0 0"/>
            <inertia ixx="0.05" ixy="0" ixz="0" iyy="0.05" iyz="0" izz="0.05" />
        </inertial>
        <visual>
            <origin xyz="0.0 0.0 0.0" rpy="0.0 0.0 0.0"/>
            <geometry>
                <cylinder radius="0.005" length="0.005"/>
            </geometry>
        </visual>
    </link>

    <!-- Joint 7 -->
    <joint name="joint7" type="revolute">
        <parent link="indexp3_c"/>
        <child link="indexp4_c"/>
        <origin xyz="0 0.000899992 0.0279039" rpy="0 0 0"/>
        <!-- -0.523599 0 0 -->
        <axis xyz="1 0 0"/>
        <limit lower="-0.875" upper="0" effort="10" velocity="1"/>
    </joint>

    <!-- Link 8 -->
    <link name="indexp5_c">
        <inertial>
            <mass value="0.5" />
            <origin xyz="0 0 0" rpy="0 0 0"/>
            <inertia ixx="0.05" ixy="0" ixz="0" iyy="0.05" iyz="0" izz="0.05" />
        </inertial>
        <visual>
            <origin xyz="0.0 0.0 0.0" rpy="0.0 0.0 0.0"/>
            <geometry>
                <cylinder radius="0.005" length="0.005"/>
            </geometry>
        </visual>
    </link>

    <!-- Joint 8 -->
    <joint name="joint8" type="fixed">
        <parent link="indexp4_c"/>
        <child link="indexp5_c"/>
        <origin xyz="-0.000036879 -0.000910405 0.02221986" rpy="0 0 0"/>
        <axis xyz="0 0 0"/>
        <limit lower="-3.14" upper="3.14" effort="10" velocity="1"/>
    </joint>

    <!-- Link 9 -->
    <link name="thumbp1_c_1">
        <inertial>
            <mass value="0.5" />
            <origin xyz="0 0 0" rpy="0 0 0"/>
            <inertia ixx="0.05" ixy="0" ixz="0" iyy="0.05" iyz="0" izz="0.05" />
        </inertial>
    </link>
    <link name="thumbp1_c_2">
        <inertial>
            <mass value="0.5" />
            <origin xyz="0 0 0" rpy="0 0 0"/>
            <inertia ixx="0.05" ixy="0" ixz="0" iyy="0.05" iyz="0" izz="0.05" />
        </inertial>
    </link>
    <link name="thumbp1_c_3">
        <inertial>
            <mass value="0.5" />
            <origin xyz="0 0 0" rpy="0 0 0"/>
            <inertia ixx="0.05" ixy="0" ixz="0" iyy="0.05" iyz="0" izz="0.05" />
        </inertial>
        <visual>
            <origin xyz="0.0 0.0 0.0" rpy="0.0 0.0 0.0"/>
            <geometry>
                <cylinder radius="0.005" length="0.005"/>
            </geometry>
        </visual>
    </link>

    <!-- Joint 9 -->
    <joint name="joint9_1" type="fixed">
        <parent link="meta1_c_3"/>
        <child link="thumbp1_c_1"/>
        <origin xyz="-0.0122179 0.0052 -0.0473596" rpy="0 -0.191986 0"/>
        <axis xyz="0 0 0"/>
        <limit lower="-3.14" upper="3.14" effort="10" velocity="1"/>
    </joint>
    <joint name="joint9_2" type="fixed">
        <parent link="thumbp1_c_1"/>
        <child link="thumbp1_c_2"/>
        <origin xyz="0 0 0" rpy="0 0 -0.083339472"/>
        <axis xyz="0 0 0"/>
        <limit lower="-3.14" upper="3.14" effort="10" velocity="1"/>
    </joint>
    <joint name="joint9_3" type="revolute">
        <parent link="thumbp1_c_2"/>
        <child link="thumbp1_c_3"/>
        <origin xyz="0 0 0" rpy="0 0 0"/>
        <!-- -0.872665 0 0 -->
        <axis xyz="1 0 0"/>
        <limit lower="-0.785" upper="0" effort="10" velocity="1"/>
    </joint>

    <!-- Link 10 -->
    <link name="thumbp2_c_1">
        <inertial>
            <mass value="0.5" />
            <origin xyz="0 0 0" rpy="0 0 0"/>
            <inertia ixx="0.05" ixy="0" ixz="0" iyy="0.05" iyz="0" izz="0.05" />
        </inertial>
    </link>
    <link name="thumbp2_c_2">
        <inertial>
            <mass value="0.5" />
            <origin xyz="0 0 0" rpy="0 0 0"/>
            <inertia ixx="0.05" ixy="0" ixz="0" iyy="0.05" iyz="0" izz="0.05" />
        </inertial>
    </link>
    <link name="thumbp2_c_3">
        <inertial>
            <mass value="0.5" />
            <origin xyz="0 0 0" rpy="0 0 0"/>
            <inertia ixx="0.05" ixy="0" ixz="0" iyy="0.05" iyz="0" izz="0.05" />
        </inertial>
        <visual>
            <origin xyz="0.0 0.0 0.0" rpy="0.0 0.0 0.0"/>
            <geometry>
                <cylinder radius="0.005" length="0.005"/>
            </geometry>
        </visual>
    </link>

    <!-- Joint 10 -->
    <joint name="joint10_1" type="fixed">
        <parent link="thumbp1_c_3"/>
        <child link="thumbp2_c_1"/>
        <origin xyz="-0.0131755 0.00349373 0.00086368" rpy="0 0 0"/>
        <axis xyz="0 0 0"/>
        <limit lower="-3.14" upper="3.14" effort="10" velocity="1"/>
    </joint>
    <joint name="joint10_2" type="fixed">
        <parent link="thumbp2_c_1"/>
        <child link="thumbp2_c_2"/>
        <origin xyz="0 0 0" rpy="0 -0.174533 0"/>
        <axis xyz="0 0 0"/>
        <limit lower="-3.14" upper="3.14" effort="10" velocity="1"/>
    </joint>
    <joint name="joint10_3" type="revolute">
        <parent link="thumbp2_c_2"/>
        <child link="thumbp2_c_3"/>
        <origin xyz="0 0 0" rpy="0 0 0"/>
        <!-- 0 0 -0.349066 -->
        <axis xyz="0 0 1"/>
        <limit lower="-0.88" upper="0.0" effort="10" velocity="1"/>
    </joint>

    <!-- Link 11 -->
    <link name="thumbp3_c">
        <inertial>
            <mass value="0.5" />
            <origin xyz="0 0 0" rpy="0 0 0"/>
            <inertia ixx="0.05" ixy="0" ixz="0" iyy="0.05" iyz="0" izz="0.05" />
        </inertial>
        <visual>
            <origin xyz="0.0 0.0 0.0" rpy="0.0 0.0 0.0"/>
            <geometry>
                <cylinder radius="0.005" length="0.005"/>
            </geometry>
        </visual>
    </link>

    <!-- Joint 11 -->
    <joint name="joint11" type="revolute">
        <parent link="thumbp2_c_3"/>
        <child link="thumbp3_c"/>
        <origin xyz="-0.0034515 0 0.0204197" rpy="0 0 0"/>
        <!-- 0 -0.523599 0 -->
        <axis xyz="0 1 0"/>
        <limit lower="-0.70" upper="0.27" effort="10" velocity="1"/>
    </joint>

    <!-- Link 12 -->
    <link name="thumbp4_c">
        <inertial>
            <mass value="0.5" />
            <origin xyz="0 0 0" rpy="0 0 0"/>
            <inertia ixx="0.05" ixy="0" ixz="0" iyy="0.05" iyz="0" izz="0.05" />
        </inertial>
        <visual>
            <origin xyz="0.0 0.0 0.0" rpy="0.0 0.0 0.0"/>
            <geometry>
                <cylinder radius="0.005" length="0.005"/>
            </geometry>
        </visual>
    </link>

    <!-- Joint 12 -->
    <joint name="joint12" type="revolute">
        <parent link="thumbp3_c"/>
        <child link="thumbp4_c"/>
        <origin xyz="-0.0012 0 0.040" rpy="0 0 0"/>
        <!-- 0 1.22173 0 -->
        <axis xyz="0 1 0"/>
        <limit lower="-0" upper="1.57" effort="10" velocity="1"/>
    </joint>

    <!-- Link 13 -->
    <link name="thumbp5_c">
        <inertial>
            <mass value="0.5" />
            <origin xyz="0 0 0" rpy="0 0 0"/>
            <inertia ixx="0.05" ixy="0" ixz="0" iyy="0.05" iyz="0" izz="0.05" />
        </inertial>
        <visual>
            <origin xyz="0.0 0.0 0.0" rpy="0.0 0.0 0.0"/>
            <geometry>
                <cylinder radius="0.005" length="0.005"/>
            </geometry>
        </visual>
    </link>

    <!-- Joint 13 -->
    <joint name="joint13" type="revolute">
        <parent link="thumbp4_c"/>
        <child link="thumbp5_c"/>
        <origin xyz="-0.0072 0 0.036" rpy="0 0 0"/>
        <!-- 0 0.785398 0 -->
        <axis xyz="0 1 0"/>
        <limit lower="-0.90" upper="1.22" effort="10" velocity="1"/>
    </joint>

    <!-- Link 14 -->
    <link name="thumbp6_c">
        <inertial>
            <mass value="0.5" />
            <origin xyz="0 0 0" rpy="0 0 0"/>
            <inertia ixx="0.05" ixy="0" ixz="0" iyy="0.05" iyz="0" izz="0.05" />
        </inertial>
        <visual>
            <origin xyz="0.0 0.0 0.0" rpy="0.0 0.0 0.0"/>
            <geometry>
                <cylinder radius="0.005" length="0.005"/>
            </geometry>
        </visual>
    </link>

    <!-- Joint 14 -->
    <joint name="joint9" type="fixed">
        <parent link="thumbp5_c"/>
        <child link="thumbp6_c"/>
        <origin xyz="0.00570894 0.003393 0.0339805" rpy="0 0 0"/>
        <axis xyz="0 0 0"/>
        <limit lower="-3.14" upper="3.14" effort="10" velocity="1"/>
    </joint>

</robot>