<?xml version="1.0"?>
<robot name="hand">

    <!-- Base Link -->
    <link name="base_link">
        <inertial>
            <mass value="1.0" />
            <origin xyz="0 0 0" rpy="0 0 0"/>
            <inertia ixx="0.1" ixy="0" ixz="0" iyy="0.1" iyz="0" izz="0.1" />
        </inertial>
        <visual>
            <origin xyz="0.0 0.0 0.0" rpy="0.0 0.0 0.0"/>
            <geometry>
                <cylinder radius="0.0" length="0.0"/>
            </geometry>
        </visual>
    </link>

    <!-- Link 1 -->
    <link name="indexp1_c_1">
        <inertial>
            <mass value="0.5" />
            <origin xyz="0 0 0" rpy="0 0 0"/>
            <inertia ixx="0.05" ixy="0" ixz="0" iyy="0.05" iyz="0" izz="0.05" />
        </inertial>
    </link>
    <link name="indexp1_c_2">
        <inertial>
            <mass value="0.5" />
            <origin xyz="0 0 0" rpy="0 0 0"/>
            <inertia ixx="0.05" ixy="0" ixz="0" iyy="0.05" iyz="0" izz="0.05" />
        </inertial>
    </link>
    <link name="indexp1_c_3">
        <inertial>
            <mass value="0.5" />
            <origin xyz="0 0 0" rpy="0 0 0"/>
            <inertia ixx="0.05" ixy="0" ixz="0" iyy="0.05" iyz="0" izz="0.05" />
        </inertial>
        <visual>
            <origin xyz="0.0 0.0 0.0" rpy="0.0 0.0 0.0"/>
            <geometry>
                <cylinder radius="0.005" length="0.005"/>
            </geometry>
        </visual>
    </link>

    <!-- Joint 1 -->
    <joint name="joint1_1" type="fixed">
        <parent link="base_link"/>
        <child link="indexp1_c_1"/>
        <origin xyz="0 0 0" rpy="-0.0028797933 0 0"/>
        <axis xyz="0 0 0"/>
        <limit lower="-3.14" upper="3.14" effort="10" velocity="1"/>
    </joint>
    <joint name="joint1_2" type="fixed">
        <parent link="indexp1_c_1"/>
        <child link="indexp1_c_2"/>
        <origin xyz="0 0 0" rpy="0 -0.04258603 0"/>
        <axis xyz="0 0 0"/>
        <limit lower="-3.14" upper="3.14" effort="10" velocity="1"/>
    </joint>
    <joint name="joint1_3" type="revolute">
        <parent link="indexp1_c_2"/>
        <child link="indexp1_c_3"/>
        <origin xyz="0 0 0" rpy="0 0 0"/>
        <axis xyz="0 0 1"/>
        <limit lower="-0.27" upper="0.27" effort="10" velocity="1"/>
    </joint>

    <!-- Link 2 -->
    <link name="indexp2_c">
        <inertial>
            <mass value="0.5" />
            <origin xyz="0 0 0" rpy="0 0 0"/>
            <inertia ixx="0.05" ixy="0" ixz="0" iyy="0.05" iyz="0" izz="0.05" />
        </inertial>
        <visual>
            <origin xyz="0.0 0.0 0.0" rpy="0.0 0.0 0.0"/>
            <geometry>
                <cylinder radius="0.005" length="0.005"/>
            </geometry>
        </visual>
    </link>

    <!-- Joint 2 -->
    <joint name="joint2" type="revolute">
        <parent link="indexp1_c_3"/>
        <child link="indexp2_c"/>
        <origin xyz="-0.000099998 0.014 -0.0016" rpy="0 0 0"/>
        <axis xyz="1 0 0"/>
        <limit lower="-1.57" upper="0.17" effort="10" velocity="1"/>
    </joint>

    <!-- Link 3 -->
    <link name="indexp3_c">
        <inertial>
            <mass value="0.5" />
            <origin xyz="0 0 0" rpy="0 0 0"/>
            <inertia ixx="0.05" ixy="0" ixz="0" iyy="0.05" iyz="0" izz="0.05" />
        </inertial>
        <visual>
            <origin xyz="0.0 0.0 0.0" rpy="0.0 0.0 0.0"/>
            <geometry>
                <cylinder radius="0.005" length="0.005"/>
            </geometry>
        </visual>
    </link>

    <!-- Joint 3 -->
    <joint name="joint3" type="revolute">
        <parent link="indexp2_c"/>
        <child link="indexp3_c"/>
        <origin xyz="0 0.048 0.00199797" rpy="0 0 0"/>
        <!-- -1.5708 0 0-->
        <axis xyz="1 0 0"/>
        <limit lower="-2.10" upper="0" effort="10" velocity="1"/>
    </joint>

    <!-- Link 4 -->
    <link name="indexp4_c">
        <inertial>
            <mass value="0.5" />
            <origin xyz="0 0 0" rpy="0 0 0"/>
            <inertia ixx="0.05" ixy="0" ixz="0" iyy="0.05" iyz="0" izz="0.05" />
        </inertial>
        <visual>
            <origin xyz="0.0 0.0 0.0" rpy="0.0 0.0 0.0"/>
            <geometry>
                <cylinder radius="0.005" length="0.005"/>
            </geometry>
        </visual>
    </link>

    <!-- Joint 4 -->
    <joint name="joint4" type="revolute">
        <parent link="indexp3_c"/>
        <child link="indexp4_c"/>
        <origin xyz="0 0.0279039 0.000899992" rpy="0 0 0"/>
        <!-- -0.523599 0 0 -->
        <axis xyz="1 0 0"/>
        <limit lower="-0.875" upper="0" effort="10" velocity="1"/>
    </joint>

    <!-- Link 5 -->
    <link name="indexp5_c">
        <inertial>
            <mass value="0.5" />
            <origin xyz="0 0 0" rpy="0 0 0"/>
            <inertia ixx="0.05" ixy="0" ixz="0" iyy="0.05" iyz="0" izz="0.05" />
        </inertial>
        <visual>
            <origin xyz="0.0 0.0 0.0" rpy="0.0 0.0 0.0"/>
            <geometry>
                <cylinder radius="0.005" length="0.005"/>
            </geometry>
        </visual>
    </link>

    <!-- Joint 5 -->
    <joint name="joint5" type="fixed">
        <parent link="indexp4_c"/>
        <child link="indexp5_c"/>
        <origin xyz="-0.000036879 0.02221986 -0.000910405" rpy="0 0 0"/>
        <axis xyz="0 0 0"/>
        <limit lower="-3.14" upper="3.14" effort="10" velocity="1"/>
    </joint>

</robot>