<?xml version="1.0"?>
<robot name="hand">

    <!-- Base Link -->
    <link name="base_link">
        <inertial>
            <mass value="1.0" />
            <origin xyz="0 0 0" rpy="0 0 0"/>
            <inertia ixx="0.1" ixy="0" ixz="0" iyy="0.1" iyz="0" izz="0.1" />
        </inertial>
        <visual>
            <origin xyz="0.0 0.0 0" rpy="0.0 0.0 0.0"/>
            <geometry>
                <cylinder radius="0.0" length="0.0"/>
            </geometry>
        </visual>
    </link>

    <!-- Link 1 -->
    <link name="thumbp1_c_1">
        <inertial>
            <mass value="0.5" />
            <origin xyz="0 0 0" rpy="0 0 0"/>
            <inertia ixx="0.05" ixy="0" ixz="0" iyy="0.05" iyz="0" izz="0.05" />
        </inertial>
    </link>
    <link name="thumbp1_c_2">
        <inertial>
            <mass value="0.5" />
            <origin xyz="0 0 0" rpy="0 0 0"/>
            <inertia ixx="0.05" ixy="0" ixz="0" iyy="0.05" iyz="0" izz="0.05" />
        </inertial>
    </link>
    <link name="thumbp1_c_3">
        <inertial>
            <mass value="0.5" />
            <origin xyz="0 0 0" rpy="0 0 0"/>
            <inertia ixx="0.05" ixy="0" ixz="0" iyy="0.05" iyz="0" izz="0.05" />
        </inertial>
        <visual>
            <origin xyz="0.0 0.0 0.0" rpy="0.0 0.0 0.0"/>
            <geometry>
                <cylinder radius="0.005" length="0.005"/>
            </geometry>
        </visual>
    </link>

    <!-- Joint 1 -->
    <joint name="joint1_1" type="fixed">
        <parent link="base_link"/>
        <child link="thumbp1_c_1"/>
        <origin xyz="0 0 0" rpy="0 -0.191986 0"/>
        <axis xyz="0 0 0"/>
        <limit lower="-3.14" upper="3.14" effort="10" velocity="1"/>
    </joint>
    <joint name="joint1_2" type="fixed">
        <parent link="thumbp1_c_1"/>
        <child link="thumbp1_c_2"/>
        <origin xyz="0 0 0" rpy="0 0 -0.083339472"/>
        <axis xyz="0 0 0"/>
        <limit lower="-3.14" upper="3.14" effort="10" velocity="1"/>
    </joint>
    <joint name="joint1_3" type="revolute">
        <parent link="thumbp1_c_2"/>
        <child link="thumbp1_c_3"/>
        <origin xyz="0 0 0" rpy="0 0 0"/>
        <!-- -0.872665 0 0 -->
        <axis xyz="1 0 0"/>
        <limit lower="-0.785" upper="0" effort="10" velocity="1"/>
    </joint>

    <!-- Link 1 -->
    <link name="thumbp2_c_1">
        <inertial>
            <mass value="0.5" />
            <origin xyz="0 0 0" rpy="0 0 0"/>
            <inertia ixx="0.05" ixy="0" ixz="0" iyy="0.05" iyz="0" izz="0.05" />
        </inertial>
    </link>
    <link name="thumbp2_c_2">
        <inertial>
            <mass value="0.5" />
            <origin xyz="0 0 0" rpy="0 0 0"/>
            <inertia ixx="0.05" ixy="0" ixz="0" iyy="0.05" iyz="0" izz="0.05" />
        </inertial>
    </link>
    <link name="thumbp2_c_3">
        <inertial>
            <mass value="0.5" />
            <origin xyz="0 0 0" rpy="0 0 0"/>
            <inertia ixx="0.05" ixy="0" ixz="0" iyy="0.05" iyz="0" izz="0.05" />
        </inertial>
        <visual>
            <origin xyz="0.0 0.0 0.0" rpy="0.0 0.0 0.0"/>
            <geometry>
                <cylinder radius="0.005" length="0.005"/>
            </geometry>
        </visual>
    </link>

    <!-- Joint 2 -->
    <joint name="joint2_1" type="fixed">
        <parent link="thumbp1_c_3"/>
        <child link="thumbp2_c_1"/>
        <origin xyz="-0.0131755 0.00349373 0.00086368" rpy="0 0 0"/>
        <axis xyz="0 0 0"/>
        <limit lower="-3.14" upper="3.14" effort="10" velocity="1"/>
    </joint>
    <joint name="joint2_2" type="fixed">
        <parent link="thumbp2_c_1"/>
        <child link="thumbp2_c_2"/>
        <origin xyz="0 0 0" rpy="0 -0.174533 0"/>
        <axis xyz="0 0 0"/>
        <limit lower="-3.14" upper="3.14" effort="10" velocity="1"/>
    </joint>
    <joint name="joint2_3" type="revolute">
        <parent link="thumbp2_c_2"/>
        <child link="thumbp2_c_3"/>
        <origin xyz="0 0 0" rpy="0 0 0"/>
        <!-- 0 0 -0.349066 -->
        <axis xyz="0 0 1"/>
        <limit lower="-0.88" upper="0.0" effort="10" velocity="1"/>
    </joint>

    <!-- Link 2 -->
    <link name="thumbp3_c">
        <inertial>
            <mass value="0.5" />
            <origin xyz="0 0 0" rpy="0 0 0"/>
            <inertia ixx="0.05" ixy="0" ixz="0" iyy="0.05" iyz="0" izz="0.05" />
        </inertial>
        <visual>
            <origin xyz="0.0 0.0 0.0" rpy="0.0 0.0 0.0"/>
            <geometry>
                <cylinder radius="0.005" length="0.005"/>
            </geometry>
        </visual>
    </link>

    <!-- Joint 3 -->
    <joint name="joint3" type="revolute">
        <parent link="thumbp2_c_3"/>
        <child link="thumbp3_c"/>
        <origin xyz="-0.0034515 0 0.0204197" rpy="0 0 0"/>
        <!-- 0 -0.523599 0 -->
        <axis xyz="0 1 0"/>
        <limit lower="-0.70" upper="0.27" effort="10" velocity="1"/>
    </joint>

    <!-- Link 4 -->
    <link name="thumbp4_c">
        <inertial>
            <mass value="0.5" />
            <origin xyz="0 0 0" rpy="0 0 0"/>
            <inertia ixx="0.05" ixy="0" ixz="0" iyy="0.05" iyz="0" izz="0.05" />
        </inertial>
        <visual>
            <origin xyz="0.0 0.0 0.0" rpy="0.0 0.0 0.0"/>
            <geometry>
                <cylinder radius="0.005" length="0.005"/>
            </geometry>
        </visual>
    </link>

    <!-- Joint 4 -->
    <joint name="joint4" type="revolute">
        <parent link="thumbp3_c"/>
        <child link="thumbp4_c"/>
        <origin xyz="-0.0012 0 0.040" rpy="0 0 0"/>
        <!-- 0 1.22173 0 -->
        <axis xyz="0 1 0"/>
        <limit lower="-0" upper="1.57" effort="10" velocity="1"/>
    </joint>

    <!-- Link 5 -->
    <link name="thumbp5_c">
        <inertial>
            <mass value="0.5" />
            <origin xyz="0 0 0" rpy="0 0 0"/>
            <inertia ixx="0.05" ixy="0" ixz="0" iyy="0.05" iyz="0" izz="0.05" />
        </inertial>
        <visual>
            <origin xyz="0.0 0.0 0.0" rpy="0.0 0.0 0.0"/>
            <geometry>
                <cylinder radius="0.005" length="0.005"/>
            </geometry>
        </visual>
    </link>

    <!-- Joint 5 -->
    <joint name="joint5" type="revolute">
        <parent link="thumbp4_c"/>
        <child link="thumbp5_c"/>
        <origin xyz="-0.0072 0 0.036" rpy="0 0 0"/>
        <!-- 0 0.785398 0 -->
        <axis xyz="0 1 0"/>
        <limit lower="-0.90" upper="1.22" effort="10" velocity="1"/>
    </joint>

    <!-- Link 6 -->
    <link name="thumbp6_c">
        <inertial>
            <mass value="0.5" />
            <origin xyz="0 0 0" rpy="0 0 0"/>
            <inertia ixx="0.05" ixy="0" ixz="0" iyy="0.05" iyz="0" izz="0.05" />
        </inertial>
        <visual>
            <origin xyz="0.0 0.0 0.0" rpy="0.0 0.0 0.0"/>
            <geometry>
                <cylinder radius="0.005" length="0.005"/>
            </geometry>
        </visual>
    </link>

    <!-- Joint 6 -->
    <joint name="joint6" type="fixed">
        <parent link="thumbp5_c"/>
        <child link="thumbp6_c"/>
        <origin xyz="0.00570894 0.003393 0.0339805" rpy="0 0 0"/>
        <axis xyz="0 0 0"/>
        <limit lower="-3.14" upper="3.14" effort="10" velocity="1"/>
    </joint>
</robot>